Workbook

Sheet Fixed Assts
B3: Fixed Assets Schedule
B4: Fiscal Year | C4: 2021 | D4: 2022 | E4: 2023 | F4: 2024 | G4: 2025 | H4: 2026 | I4: 2027 | J4: 2028 | K4: 2029 | L4: 2030
B5: Beginning PP&E | C5: =C8+C6-C7 -> 5365 | D5: =C8 -> 5571.7 | E5: =D8 -> 5817.2 | F5: =E8 -> 5841 | G5: =F8 -> 5782 | H5: =G8 -> 5946 | I5: =H8 -> 5973.6185 | J5: =I8 -> 5851.1616 | K5: =J8 -> 5548.7213 | L5: =K8 -> 5031.2192
B6: Depreciation & Ammortization | C6: =-'Free Cash Flow'!B10 -> 807 | D6: =-'Free Cash Flow'!C10 -> 860.3 | E6: =-'Free Cash Flow'!D10 -> 950.4 | F6: =-'Free Cash Flow'!E10 -> 1008 | G6: =-'Free Cash Flow'!F10 -> 962 | H6: =-'Free Cash Flow'!G10 -> 1093.5955 | I6: =-'Free Cash Flow'!H10 -> 1277.5083 | J6: =-'Free Cash Flow'!I10 -> 1492.3502 | ... L6: =-'Free Cash Flow'!K10 -> 2036.5016
B7: CapEx | C7: =-'Cash flow'!C18 -> 1013.7 | D7: =-'Cash flow'!D18 -> 1004 | E7: =-'Cash flow'!E18 -> 1212.6 | F7: =-'Cash flow'!F18 -> 970.4 | G7: =-'Cash flow'!G18 -> 1189 | H7: =-'Cash flow'!H18 -> 1121.214 | I7: =-'Cash flow'!I18 -> 1155.0514 | J7: =-'Cash flow'!J18 -> 1189.9099 | ... L7: =-'Cash flow'!L18 -> 1262.8148
B8: Ending PP&E | C8: ='Balance sheet'!C6 -> 5571.7 | D8: ='Balance sheet'!D6 -> 5817.2 | E8: ='Balance sheet'!E6 -> 5841 | F8: ='Balance sheet'!F6 -> 5782 | G8: ='Balance sheet'!G6 -> 5946 | H8: =H5-H6+H7 -> 5973.6185 | I8: =I5-I6+I7 -> 5851.1616 | J8: =J5-J6+J7 -> 5548.7213 | K8: =K5-K6+K7 -> 5031.2192 | L8: =L5-L6+L7 -> 4257.5324

Sheet Net Working Capital
B2: Networking Capital
B3: years | D3: 2021 | E3: 2022 | F3: 2023 | G3: 2024 | H3: 2025 | I3: 2026 | J3: 2027 | K3: 2028 | L3: 2029 | M3: 2030
B4: CURRENT ASSETS
B5: Inventories | D5: ='Balance sheet'!C17 -> 5741.1 | E5: ='Balance sheet'!D17 -> 7124.4 | F5: ='Balance sheet'!E17 -> 7503.6 | G5: ='Balance sheet'!F17 -> 7422.9 | H5: ='Balance sheet'!G17 -> 6042 | I5: ='Balance sheet'!H17 -> 6924.7818 | J5: ='Balance sheet'!I17 -> 7084.0518 | K5: ='Balance sheet'!J17 -> 7246.985 | ... M5: ='Balance sheet'!L17 -> 7584.18
B6: Trade and other receivables | D6: ='Balance sheet'!C18 -> 3295.1 | E6: ='Balance sheet'!D18 -> 3955.6 | F6: ='Balance sheet'!E18 -> 4632 | G6: ='Balance sheet'!F18 -> 4277 | H6: ='Balance sheet'!G18 -> 4170 | I6: ='Balance sheet'!H18 -> 4331.9669 | J6: ='Balance sheet'!I18 -> 4462.7022 | K6: ='Balance sheet'!J18 -> 4597.3831 | ... M6: ='Balance sheet'!L18 -> 4879.0611
B7: Cash and cash equivalents | D7: ='Balance sheet'!C21 -> 2161.8 | E7: ='Balance sheet'!D21 -> 1115.9 | F7: ='Balance sheet'!E21 -> 844 | G7: ='Balance sheet'!F21 -> 1625 | H7: ='Balance sheet'!G21 -> 3069 | I7: ='Balance sheet'!H21 -> 5896 | J7: ='Balance sheet'!I21 -> 8722 | K7: ='Balance sheet'!J21 -> 12210 | ... M7: ='Balance sheet'!L21 -> 21260
B8: Total current assets | D8: ='Balance sheet'!C22 -> 11198 | E8: ='Balance sheet'!D22 -> 12196 | F8: ='Balance sheet'!E22 -> 13037 | G8: ='Balance sheet'!F22 -> 13423 | H8: ='Balance sheet'!G22 -> 15088 | I8: ='Balance sheet'!H22 -> 10227.967 | J8: ='Balance sheet'!I22 -> 20268.754 | K8: ='Balance sheet'!J22 -> 24054.368 | ... M8: ='Balance sheet'!L22 -> 33723.241
B10: CURRENT LIABILITIES
B11: Trade and other payables | D11: ='Balance sheet'!C45 -> 5131.5 | E11: ='Balance sheet'!D45 -> 5677.7 | F11: ='Balance sheet'!E45 -> 4373 | G11: ='Balance sheet'!F45 -> 4880 | H11: ='Balance sheet'!G45 -> 6293 | I11: ='Balance sheet'!H45 -> 5274.2017 | J11: ='Balance sheet'!I45 -> 5395.5083 | K11: ='Balance sheet'!J45 -> 5519.605 | ... M11: ='Balance sheet'!L45 -> 5776.4267
B12: Employee-related accruals | D12: ='Balance sheet'!C47 -> 527.1 | E12: ='Balance sheet'!D47 -> 464.4 | F12: ='Balance sheet'!E47 -> 428 | G12: ='Balance sheet'!F47 -> 465 | H12: ='Balance sheet'!G47 -> 564 | I12: ='Balance sheet'!H47 -> 490.4993 | J12: ='Balance sheet'!I47 -> 505.30218 | K12: ='Balance sheet'!J47 -> 520.5518 | ... M12: ='Balance sheet'!L47 -> 552.4456
B13: Taxation | D13: ='Balance sheet'!C49 -> 156.7 | E13: ='Balance sheet'!D49 -> 126.6 | F13: ='Balance sheet'!E49 -> 117 | G13: ='Balance sheet'!F49 -> 69 | H13: ='Balance sheet'!G49 -> 588 | I13: ='Balance sheet'!H49 -> 222.4419 | J13: ='Balance sheet'!I49 -> 235.19754 | K13: ='Balance sheet'!J49 -> 249.05876 | ... M13: ='Balance sheet'!L49 -> 279.50386
B14: Short-term borrowings | D14: ='Balance sheet'!C50 -> 168.3 | E14: ='Balance sheet'!D50 -> 1167.2 | F14: ='Balance sheet'!E50 -> 883.7 | G14: ='Balance sheet'!F50 -> 939.1 | H14: ='Balance sheet'!G50 -> 116 | I14: ='Balance sheet'!H50 -> 116 | J14: ='Balance sheet'!I50 -> 116 | K14: ='Balance sheet'!J50 -> 116 | ... M14: ='Balance sheet'!L50 -> 116
B15: Total current liabilities | D15: ='Balance sheet'!C51 -> 5983.6 | E15: ='Balance sheet'!D51 -> 7435.9 | F15: ='Balance sheet'!E51 -> 6761 | G15: ='Balance sheet'!F51 -> 7305 | H15: ='Balance sheet'!G51 -> 8626 | I15: ='Balance sheet'!H51 -> 6103.1429 | J15: ='Balance sheet'!I51 -> 6252.0081 | K15: ='Balance sheet'!J51 -> 6405.2156 | ... M15: ='Balance sheet'!L51 -> 6724.3762
B17: NWC | D17: =(D5+D6)-(D11+D12) -> 3377.6 | E17: =(E5+E6)-(E11+E12) -> 4937.9 | F17: =(F5+F6)-(F11+F12) -> 7334.6 | G17: =(G5+G6)-(G11+G12) -> 6354.9 | H17: =(H5+H6)-(H11+H12) -> 3355 | I17: =(I5+I6)-(I11+I12) -> 5492.0477 | J17: =(J5+J6)-(J11+J12) -> 5645.9435 | K17: =(K5+K6)-(K11+K12) -> 5804.2113 | ... M17: =(M5+M6)-(M11+M12) -> 6134.3688

Sheet WACC
C2: Weighted Average Cost of Capital
C3: Equity | D3: ='Balance sheet'!G36 -> 17239
C4: Debts | D4: 357
C6: Cost of Debt | D6: =-'Income Statemnt'!G23/WACC!D4 -> 0.20168067
C7: Tax Rate | D7: 0.27
C8: D/(D+E) | D8: =D4/SUM(D3:D4) -> 0.020288702
C9: After Tax Cost of Debt | D9: =D6*(1-D7) -> 0.14722689
C11: Risk Free Rate ( 10-Yr Treasury Yield) | D11: 0.086
C12: Expected Market Return | D12: 0.15
C13: Market risk Premium | D13: =D12-D11 -> 0.064
C14: Levered Beta | D14: 0.02
C15: E/(D+E) | D15: =D3/(D3+D4) -> 0.9797113
C16: Cost of Equity | D16: =D11+D14*(D13-D11) -> 0.08556
C19: WACC | D19: =D9*D8+D16*D15 -> 0.086811141

Sheet DCF
A1: R'million
B3: Unlevered Free Cash Flow (mm)
B4: Fiscal Year | D4: 2021 | E4: 2022 | F4: 2023 | G4: 2024 | H4: 2025 | I4: 2026 | J4: 2027 | K4: 2028 | L4: 2029 | M4: 2030
B5: Unlevered Free Cash Flow | D5: ='Free Cash Flow'!B22 -> 573.4 | E5: ='Free Cash Flow'!C22 -> -359.5 | F5: ='Free Cash Flow'!D22 -> -1592.4 | G5: ='Free Cash Flow'!E22 -> 1968.6 | H5: ='Free Cash Flow'!F22 -> 1864 | I5: ='Free Cash Flow'!G22 -> 8113.2804 | J5: ='Free Cash Flow'!H22 -> -5483.6167 | K5: ='Free Cash Flow'!I22 -> 1510.7417 | ... M5: ='Free Cash Flow'!K22 -> 1644.9295
B7: Projection Year | I7: 1 | J7: 2 | K7: 3 | L7: 4 | M7: 5
B8: Present Value of Free Cash Flow | I8: =I5/(1+$C$13)^(I7) -> 7465.2165 | J8: =J5/(1+$C$13)^(J7) -> -4642.575 | K8: =K5/(1+$C$13)^(K7) -> 1176.8686 | L8: =L5/(1+$C$13)^(L7) -> 1131.7529 | M8: =M5/(1+$C$13)^(M7) -> 1084.8679
B10: Implied Share Price Calculation | E10: Sensitivity Table
B11: Sum of PV of FCF | C11: =I8+J8+L8+K8+M8 -> 6216.1308
B12: Growth Rate | C12: 0.027 | G12: Growth Rate
B13: WACC | C13: =WACC!D19 -> 0.086811141 | F13: =C22 -> 327.5971 | G13: 0.013 | H13: 0.018 | I13: 0.023 | J13: 0.028 | K13: 0.033
B14: Terminal Value | C14: =(M5*(1+C12))/(C13-C12) -> 28244.614 | E14: WACC | F14: 0.076811141 | G14: 309.51742 | H14: 336.01494 | I14: 367.43663 | J14: 405.29572 | K14: 451.79624
B15: PV of Terminal Value | C15: =C14/((1+C13)^(M7)) -> 18627.957 | F15: 0.081811141 | G15: 285.66934 | H15: 308.20843 | I15: 334.57997 | J15: 365.85227 | K15: 403.53137
B16: Enterprise Value | C16: =C15+C14 -> 46872.571 | F16: =C13 -> 0.086811141 | G16: 285.66934 | H16: 308.20843 | I16: 334.57997 | J16: 365.85227 | K16: 403.53137
B17: (+) Cash | C17: ='Balance sheet'!G21 -> 3069 | F17: 0.091811141 | G17: 247.23139 | H17: 264.0906 | I17: 283.39989 | J17: 305.73518 | K17: 331.86826
B18: (-) Debt | C18: =WACC!D4 -> 357 | F18: 0.096811141 | G18: 231.5333 | H18: 246.3169 | I18: 263.1034 | J18: 282.32939 | K18: 304.56834
B19: (-) Minority Interest | C19: ='Balance sheet'!G35 -> 255
B20: Equity Value | C20: =C16+C17-C18-C19 -> 49329.571
B21: Diluted Shares Outstanding (mm) | C21: 150.58
B22: Implied Share Price | C22: =C20/C21 -> 327.5971
B26: Current Market Price is | C26: 284.43
B27: Valuation Varience | C27: =(C22-C26)/C26 -> 0.15176703
D29: Investment Recommendation | G29: BUY

Sheet Scenario Analysis
A1: Scenario Analysis
B2: Forecasted | O2: 2026 | P2: 207 | Q2: 2028 | R2: 2029 | S2: 2030 | U2: Assumption
A3: (R'million) | B3: 2026 | C3: 2027 | D3: 2028 | E3: 2029 | F3: 2030 | M3: Revanue Scenarios | U3: Producer Price Index (PPI) worst | V3: =12% -> 0.12
A4: Revenue | H4: Choose Scenario -> | I4: 3 | M4: 1. Base | O4: ='Income Statemnt'!H6 -> 35429.923 | P4: ='Income Statemnt'!I6 -> 36499.171 | Q4: ='Income Statemnt'!J6 -> 37600.687 | R4: ='Income Statemnt'!K6 -> 38735.446 | S4: ='Income Statemnt'!L6 -> 39904.451 | U4: Producer Price Index (PPI) best case | V4: 0.015
A5: Total revenue | B5: =CHOOSE($I$4,O4,O5,O6) -> 35314.076 | C5: =CHOOSE($I$4,P4,P5,P6) -> 36260.874 | D5: =CHOOSE($I$4,Q4,Q5,Q6) -> 37233.056 | E5: =CHOOSE($I$4,R4,R5,R6) -> 38231.303 | F5: =CHOOSE($I$4,S4,S5,S6) -> 39256.313 | M5: 2. Best | O5: ='Income Statemnt'!G6*(1+'Income Statemnt'!$P$6) -> 37808.545 | P5: =O5*(1+'Income Statemnt'!$P$6) -> 41564.494 | Q5: =P5*(1+'Income Statemnt'!$P$6) -> 45693.564 | R5: =Q5*(1+'Income Statemnt'!$P$6) -> 50232.822 | S5: =R5*(1+'Income Statemnt'!$P$6) -> 55223.014
A6: Total cost of sales | B6: =CHOOSE($I$4,O9,O10,O11) -> -26454.4 | C6: =CHOOSE($I$4,P9,P10,P11) -> -27062.851 | D6: =CHOOSE($I$4,Q9,Q10,Q11) -> -27685.297 | E6: =CHOOSE($I$4,R9,R10,R11) -> -28322.059 | F6: =CHOOSE($I$4,S9,S10,S11) -> -28973.466 | M6: 3. Worst | O6: ='Income Statemnt'!G6*(1+'Income Statemnt'!$S$6) -> 35314.076 | P6: =O6*(1+'Income Statemnt'!$S$6) -> 36260.874 | Q6: =P6*(1+'Income Statemnt'!$S$6) -> 37233.056 | R6: =Q6*(1+'Income Statemnt'!$S$6) -> 38231.303 | S6: =R6*(1+'Income Statemnt'!$S$6) -> 39256.313 | U6: CPI best case | V6: 0.035
A7: Gross profit | B7: =B5+B6 -> 8859.6761 | C7: =C5+C6 -> 9198.0225 | D7: =D5+D6 -> 9547.759 | E7: =E5+E6 -> 9909.2441 | F7: =F5+F6 -> 10282.848 | U7: CPI worst case | V7: 0.075
M8: Cost of sales Scenarios | U8: CPI actual | V8: 0.045
A9: Operating Expenses | M9: 1. Base | O9: ='Income Statemnt'!H7 -> -24163.26 | P9: ='Income Statemnt'!I7 -> -24719.015 | Q9: ='Income Statemnt'!J7 -> -25287.552 | R9: ='Income Statemnt'!K7 -> -25869.166 | S9: ='Income Statemnt'!L7 -> -26464.157
A10: Total Expenses | B10: =CHOOSE($I$4,O14,O15,O16) -> -7630.35 | C10: =CHOOSE($I$4,P14,P15,P16) -> -7973.7157 | D10: =CHOOSE($I$4,Q14,Q15,Q16) -> -8332.533 | E10: =CHOOSE($I$4,R14,R15,R16) -> -8707.4969 | F10: =CHOOSE($I$4,S14,S15,S16) -> -9099.3343 | M10: 2. Best | O10: ='Income Statemnt'!G7*(1+V4) -> -23974.3 | P10: ='Income Statemnt'!H7*(1+W4) -> -24163.26 | Q10: ='Income Statemnt'!I7*(1+X4) -> -24719.015 | R10: ='Income Statemnt'!J7*(1+Y4) -> -25287.552 | S10: ='Income Statemnt'!K7*(1+Z4) -> -25869.166
A11: Operating income after impairments(EBIT) | B11: =B7+B10 -> 1229.3261 | C11: =C7+C10 -> 1224.3068 | D11: =D7+D10 -> 1215.226 | E11: =E7+E10 -> 1201.7472 | F11: =F7+F10 -> 1183.5132 | M11: 3. Worst | O11: ='Income Statemnt'!G7*(1+$V3) -> -26454.4 | P11: ='Income Statemnt'!H7*(1+$V3) -> -27062.851 | Q11: ='Income Statemnt'!I7*(1+$V3) -> -27685.297 | R11: ='Income Statemnt'!J7*(1+$V3) -> -28322.059 | S11: ='Income Statemnt'!K7*(1+$V3) -> -28973.466 | U11: Tax Policy Rate worst case | V11: 0.3
A12: Finance costs | B12: =CHOOSE($I$4,O19,O20,O21) -> 21.29524 | C12: =CHOOSE($I$4,P19,P20,P21) -> 21.29524 | D12: =CHOOSE($I$4,Q19,Q20,Q21) -> 21.29524 | E12: =CHOOSE($I$4,R19,R20,R21) -> 21.29524 | F12: =CHOOSE($I$4,S19,S20,S21) -> 21.29524 | U12: Tax Policy Rate best case | V12: 0.25
A13: Finance income | B13: =CHOOSE($I$4,O39,O40,O41) -> 7.6365991 | C13: =CHOOSE($I$4,P39,P40,P41) -> 11.296882 | D13: =CHOOSE($I$4,Q39,Q40,Q41) -> 15.814599 | E13: =CHOOSE($I$4,R39,R40,R41) -> 21.215654 | F13: =CHOOSE($I$4,S39,S40,S41) -> 27.536312 | M13: Operating expesnses | U13: Tax policy rate (actual) | V13: 0.27
A14: Investment income | B14: =CHOOSE($I$4,O24,O25,O26) -> 17.001307 | C14: =CHOOSE($I$4,P24,P25,P26) -> 17.457125 | D14: =CHOOSE($I$4,Q24,Q25,Q26) -> 17.925164 | E14: =CHOOSE($I$4,R24,R25,R26) -> 18.405752 | F14: =CHOOSE($I$4,S24,S25,S26) -> 18.899224 | M14: 1. Base | O14: ='Income Statemnt'!H10 -> -7417.41 | P14: ='Income Statemnt'!I10 -> -7751.1934 | Q14: ='Income Statemnt'!J10 -> -8099.9972 | R14: ='Income Statemnt'!K10 -> -8464.497 | S14: ='Income Statemnt'!L10 -> -8845.3994
A15: Income from associated companies | B15: =CHOOSE($I$4,O29,O30,O31) -> 386.08085 | C15: =CHOOSE($I$4,P29,P30,P31) -> 396.43198 | D15: =CHOOSE($I$4,Q29,Q30,Q31) -> 407.06062 | E15: =CHOOSE($I$4,R29,R30,R31) -> 417.97423 | F15: =CHOOSE($I$4,S29,S30,S31) -> 429.18044 | M15: 2. Best | O15: ='Income Statemnt'!G10*(1+$V$6) -> -7346.43 | P15: ='Income Statemnt'!H10*(1+$V$6) -> -7677.0193 | Q15: ='Income Statemnt'!I10*(1+$V$6) -> -8022.4852 | R15: ='Income Statemnt'!J10*(1+$V$6) -> -8383.4971 | S15: ='Income Statemnt'!K10*(1+$V$6) -> -8760.7544
M16: 3. Worst | O16: ='Income Statemnt'!G10*(1+$V7) -> -7630.35 | P16: ='Income Statemnt'!H10*(1+$V7) -> -7973.7157 | Q16: ='Income Statemnt'!I10*(1+$V7) -> -8332.533 | R16: ='Income Statemnt'!J10*(1+$V7) -> -8707.4969 | S16: ='Income Statemnt'!K10*(1+$V7) -> -9099.3343
A17: Profit before taxation | B17: =B11+B12+B14+B15+B13 -> 1661.3401 | C17: =C11+C12+C14+C15+C13 -> 1670.788 | D17: =D11+D12+D14+D15+D13 -> 1677.3216 | E17: =E11+E12+E14+E15+E13 -> 1680.638 | F17: =F11+F12+F14+F15+F13 -> 1680.4244
A18: Taxation & Profit | M18: Finance Cost
A19: Taxation | B19: =CHOOSE($I$4,O34,O35,O36) -> -1343.8813 | C19: =CHOOSE($I$4,P34,P35,P36) -> -1420.9444 | D19: =CHOOSE($I$4,Q34,Q35,Q36) -> -1504.6868 | E19: =CHOOSE($I$4,R34,R35,R36) -> -1593.6099 | F19: =CHOOSE($I$4,S34,S35,S36) -> -1688.6207 | M19: 1. Base | O19: ='Income Statemnt'!H23 -> -56.941291 | P19: ='Income Statemnt'!I23 -> -56.941291 | Q19: ='Income Statemnt'!J23 -> -56.941291 | R19: ='Income Statemnt'!K23 -> -56.941291 | S19: ='Income Statemnt'!L23 -> -56.941291
A20: Profit for year | B20: =B17+B19 -> 317.45881 | C20: =C17+C19 -> 249.84362 | D20: =D17+D19 -> 172.63479 | E20: =E17+E19 -> 87.028157 | F20: =F17+F19 -> -8.1963278 | M20: 2. Best | O20: =(('Balance sheet'!H50+'Balance sheet'!H41)/2)*'Income Statemnt'!$R$10 -> 88.81169 | P20: =(('Balance sheet'!I50+'Balance sheet'!I41)/2)*'Income Statemnt'!$R$10 -> 88.81169 | Q20: =(('Balance sheet'!J50+'Balance sheet'!J41)/2)*'Income Statemnt'!$R$10 -> 88.81169 | R20: =(('Balance sheet'!K50+'Balance sheet'!K41)/2)*'Income Statemnt'!$R$10 -> 88.81169 | S20: =(('Balance sheet'!L50+'Balance sheet'!L41)/2)*'Income Statemnt'!$R$10 -> 88.81169
M21: 3. Worst | O21: =(('Balance sheet'!H50+'Balance sheet'!H41)/2)*'Income Statemnt'!$P$10 -> 21.29524 | P21: =(('Balance sheet'!I50+'Balance sheet'!I41)/2)*'Income Statemnt'!$P$10 -> 21.29524 | Q21: =(('Balance sheet'!J50+'Balance sheet'!J41)/2)*'Income Statemnt'!$P$10 -> 21.29524 | R21: =(('Balance sheet'!K50+'Balance sheet'!K41)/2)*'Income Statemnt'!$P$10 -> 21.29524 | S21: =(('Balance sheet'!L50+'Balance sheet'!L41)/2)*'Income Statemnt'!$P$10 -> 21.29524
M23: Investment income
M24: 1. Base | O24: ='Income Statemnt'!H26 -> 19 | P24: ='Income Statemnt'!I26 -> 19 | Q24: ='Income Statemnt'!J26 -> 22.055422 | R24: ='Income Statemnt'!K26 -> 22.721038 | S24: ='Income Statemnt'!L26 -> 23.406741
M25: 2. Best | O25: =O5*'Income Statemnt'!$P$13 -> 25.221326 | P25: =P5*'Income Statemnt'!$P$13 -> 27.726845 | Q25: =Q5*'Income Statemnt'!$P$13 -> 30.481265 | R25: =R5*'Income Statemnt'!$P$13 -> 33.509313 | S25: =S5*'Income Statemnt'!$P$13 -> 36.838171
M26: 3. Worst | O26: =O6*'Income Statemnt'!$Q$13 -> 17.001307 | P26: =P6*'Income Statemnt'!$Q$13 -> 17.457125 | Q26: =Q6*'Income Statemnt'!$Q$13 -> 17.925164 | R26: =R6*'Income Statemnt'!$Q$13 -> 18.405752 | S26: =S6*'Income Statemnt'!$Q$13 -> 18.899224
M28: Income from associated Companies
M29: 1. Base | O29: ='Income Statemnt'!H27 -> 541.38022 | P29: ='Income Statemnt'!I27 -> 557.71864 | Q29: ='Income Statemnt'!J27 -> 574.55015 | R29: ='Income Statemnt'!K27 -> 591.88963 | S29: ='Income Statemnt'!L27 -> 609.75239
M30: 2. Best | O30: =O5*'Income Statemnt'!$R$12 -> 817.2624 | P30: =P5*'Income Statemnt'!$R$12 -> 898.45029 | Q30: =Q5*'Income Statemnt'!$R$12 -> 987.70349 | R30: =R5*'Income Statemnt'!$R$12 -> 1085.8232 | S30: =S5*'Income Statemnt'!$R$12 -> 1193.6903
M31: 3. Worst | O31: =O6*'Income Statemnt'!$S$12 -> 386.08085 | P31: =P6*'Income Statemnt'!$S$12 -> 396.43198 | Q31: =Q6*'Income Statemnt'!$S$12 -> 407.06062 | R31: =R6*'Income Statemnt'!$S$12 -> 417.97423 | S31: =S6*'Income Statemnt'!$S$12 -> 429.18044
M33: Taxation
M34: 1. Base | O34: ='Income Statemnt'!H32 -> -1209.4931 | P34: ='Income Statemnt'!I32 -> -1278.8499 | Q34: ='Income Statemnt'!J32 -> -1354.2182 | R34: ='Income Statemnt'!K32 -> -1434.2489 | S34: ='Income Statemnt'!L32 -> -1519.7587
M35: 2. Best | O35: =-'Income Statemnt'!H29*$V12 -> -1119.901 | P35: =-'Income Statemnt'!I29*$V12 -> -1184.1203 | Q35: =-'Income Statemnt'!J29*$V12 -> -1253.9057 | R35: =-'Income Statemnt'!K29*$V12 -> -1328.0082 | S35: =-'Income Statemnt'!L29*$V12 -> -1407.184
M36: 3. Worst | O36: =-'Income Statemnt'!H29*$V$11 -> -1343.8813 | P36: =-'Income Statemnt'!I29*$V$11 -> -1420.9444 | Q36: =-'Income Statemnt'!J29*$V$11 -> -1504.6868 | R36: =-'Income Statemnt'!K29*$V$11 -> -1593.6099 | S36: =-'Income Statemnt'!L29*$V$11 -> -1688.6207
M38: Finance income
M39: 1. Base | O39: ='Income Statemnt'!H24 -> 126.91178 | P39: ='Income Statemnt'!I24 -> 187.74161 | Q39: ='Income Statemnt'!J24 -> 262.82103 | R39: ='Income Statemnt'!K24 -> 352.58055 | S39: ='Income Statemnt'!L24 -> 457.62287
M40: 2. Best | O40: ='Balance sheet'!H21*'Income Statemnt'!$S$11 -> 263.19713 | P40: ='Balance sheet'!I21*'Income Statemnt'!$S$11 -> 389.34963 | Q40: ='Balance sheet'!J21*'Income Statemnt'!$S$11 -> 545.05376 | R40: ='Balance sheet'!K21*'Income Statemnt'!$S$11 -> 731.20235 | S40: ='Balance sheet'!L21*'Income Statemnt'!$S$11 -> 949.04529
M41: 3. Worst | O41: ='Balance sheet'!H21*'Income Statemnt'!$O$11 -> 7.6365991 | P41: ='Balance sheet'!I21*'Income Statemnt'!$O$11 -> 11.296882 | Q41: ='Balance sheet'!J21*'Income Statemnt'!$O$11 -> 15.814599 | R41: ='Balance sheet'!K21*'Income Statemnt'!$O$11 -> 21.215654 | S41: ='Balance sheet'!L21*'Income Statemnt'!$O$11 -> 27.536312
D55: Sensitivity Table
F57: Growth Rate
D59: WACC

Sheet Free Cash Flow
A2: Unlevered Free Cash Flow (mm) | B2: Actual | G2: Forecasted | N2: Deprecaiation Assumptions as a % of PPE
B3: 2021 | C3: 2022 | D3: 2023 | E3: 2024 | F3: 2025 | G3: 2026 | H3: 2027 | I3: 2028 | J3: 2029 | K3: 20230 | N3: 2021 | O3: 2022 | P3: 2023 | Q3: 2024 | R3: 2025 | S3: AAG
A4: Revenue | B4: ='Income Statemnt'!C6 -> 30953.9 | C4: ='Income Statemnt'!D6 -> 34028.9 | D4: ='Income Statemnt'!E6 -> 37388.5 | E4: ='Income Statemnt'!F6 -> 33494 | F4: ='Income Statemnt'!G6 -> 34392 | G4: ='Income Statemnt'!H6 -> 35429.923 | H4: ='Income Statemnt'!I6 -> 36499.171 | I4: ='Income Statemnt'!J6 -> 37600.687 | ... K4: ='Income Statemnt'!L6 -> 39904.451 | N4: =-B10/'Balance sheet'!C6 -> 0.1448391 | O4: =-C10/'Balance sheet'!D6 -> 0.14788902 | P4: =-D10/'Balance sheet'!E6 -> 0.16271186 | Q4: =-E10/'Balance sheet'!F6 -> 0.17433414 | R4: =-F10/'Balance sheet'!G6 -> 0.16178944 | S4: =AVERAGE(N4:Q4) -> 0.15744353
A5: Total cost of sales | B5: ='Income Statemnt'!C7 -> -22143.7 | C5: ='Income Statemnt'!D7 -> -23713.1 | D5: ='Income Statemnt'!E7 -> -27048.2 | E5: ='Income Statemnt'!F7 -> -23740 | F5: ='Income Statemnt'!G7 -> -23620 | G5: ='Income Statemnt'!H7 -> -24163.26 | H5: ='Income Statemnt'!I7 -> -24719.015 | I5: ='Income Statemnt'!J7 -> -25287.552 | ... K5: ='Income Statemnt'!L7 -> -26464.157
A6: Gross profit | B6: =B4+B5 -> 8810.2 | C6: =C4+C5 -> 10315.8 | D6: =D4+D5 -> 10340.3 | E6: =E4+E5 -> 9754 | F6: =F4+F5 -> 10772 | G6: =G4+G5 -> 11266.663 | H6: =H4+H5 -> 11780.156 | I6: =I4+I5 -> 12313.135 | ... K6: =K4+K5 -> 13440.295
A7: Total Expense | B7: ='Income Statemnt'!C10 -> -6626.4 | C7: ='Income Statemnt'!D10 -> -7091.4 | D7: ='Income Statemnt'!E10 -> -7449 | E7: ='Income Statemnt'!F10 -> -7030 | F7: ='Income Statemnt'!G10 -> -7098 | G7: ='Income Statemnt'!H10 -> -7417.41 | H7: ='Income Statemnt'!I10 -> -7751.1934 | I7: ='Income Statemnt'!J10 -> -8099.9972 | ... K7: ='Income Statemnt'!L10 -> -8845.3994
A9: EBITDA | B9: =B6+B7 -> 2183.8 | C9: =C6+C7 -> 3224.4 | D9: =D6+D7 -> 2891.3 | E9: =E6+E7 -> 2724 | F9: =F6+F7 -> 3674 | G9: =G6+G7 -> 3849.2535 | H9: =H6+H7 -> 4028.9623 | I9: =I6+I7 -> 4213.1375 | ... K9: =K6+K7 -> 4594.8951
A10: Depreciciation | B10: -807 | C10: -860.3 | D10: -950.4 | E10: -1008 | F10: -962 | G10: =-'Balance sheet'!H6*S4 -> -1093.5955 | H10: =-'Balance sheet'!I6*$S$4 -> -1277.5083 | I10: =-'Balance sheet'!J6*$S$4 -> -1492.3502 | J10: =-'Balance sheet'!K6*$S$4 -> -1743.3225 | K10: =-'Balance sheet'!L6*$S$4 -> -2036.5016
A12: Operating Profit | B12: =B9+B10 -> 1376.8 | C12: =C9+C10 -> 2364.1 | D12: =D9+D10 -> 1940.9 | E12: =E9+E10 -> 1716 | F12: =F9+F10 -> 2712 | G12: =G9+G10 -> 2755.658 | H12: =H9+H10 -> 2751.454 | I12: =I9+I10 -> 2720.7873 | ... K12: =K9+K10 -> 2558.3935
A13: Operating Taxes | B13: ='Income Statemnt'!C32 -> -596.7 | C13: ='Income Statemnt'!D32 -> -1019.5 | D13: ='Income Statemnt'!E32 -> -817.1 | E13: ='Income Statemnt'!F32 -> -724 | F13: ='Income Statemnt'!G32 -> -1912 | G13: ='Income Statemnt'!H32 -> -1209.4931 | H13: ='Income Statemnt'!I32 -> -1278.8499 | I13: ='Income Statemnt'!J32 -> -1354.2182 | ... K13: ='Income Statemnt'!L32 -> -1519.7587
A15: NOPAT (Net Operating Profit after Taxes) | B15: =B12+B13 -> 780.1 | C15: =C12+C13 -> 1344.6 | D15: =D12+D13 -> 1123.8 | E15: =E12+E13 -> 992 | F15: =F12+F13 -> 800 | G15: =G12+G13 -> 1546.1648 | H15: =H12+H13 -> 1472.604 | I15: =I12+I13 -> 1366.5691 | ... K15: =K12+K13 -> 1038.6349
A16: (+) Depreciation and Amortization | B16: =B10 -> -807 | C16: =C10 -> -860.3 | D16: =D10 -> -950.4 | E16: =E10 -> -1008 | F16: =F10 -> -962 | G16: =G10 -> -1093.5955 | H16: =H10 -> -1277.5083 | I16: =I10 -> -1492.3502 | ... K16: =K10 -> -2036.5016
A17: (-) Capital Expenditure | B17: ='Cash flow'!C18 -> -1013.7 | C17: ='Cash flow'!D18 -> -1004 | D17: ='Cash flow'!E18 -> -1212.6 | E17: ='Cash flow'!F18 -> -970.4 | F17: ='Cash flow'!G18 -> -1189 | G17: ='Cash flow'!H18 -> -1121.214 | H17: ='Cash flow'!I18 -> -1155.0514 | I17: ='Cash flow'!J18 -> -1189.9099 | ... K17: ='Cash flow'!L18 -> -1262.8148
A18: (-)Change in NWC | C18: =C19-B19 -> 1560.4 | D18: =D19-C19 -> 2454 | E18: =E19-D19 -> -939 | F18: =F19-E19 -> -1291 | G18: =G19-F19 -> -6594.7341 | H18: =H19-G19 -> 7078.6776 | I18: =I19-H19 -> 158.26772 | J18: =J19-I19 -> 162.7653 | K18: =K19-J19 -> 167.3922
A19: NWC | B19: =B20-B21 -> 3377.6 | C19: =C20-C21 -> 4938 | D19: =D20-D21 -> 7392 | E19: =E20-E21 -> 6453 | F19: =F20-F21 -> 5162 | G19: =G20-G21 -> -1432.7341 | H19: =H20-H21 -> 5645.9435 | I19: =I20-I21 -> 5804.2113 | ... K19: =K20-K21 -> 6134.3688
A20: Current Assts | B20: ='Net Working Capital'!D8-'Net Working Capital'!D7 -> 9036.2 | C20: ='Net Working Capital'!E8-'Net Working Capital'!E7 -> 11080.1 | D20: ='Net Working Capital'!F8-'Net Working Capital'!F7 -> 12193 | E20: ='Net Working Capital'!G8-'Net Working Capital'!G7 -> 11798 | F20: ='Net Working Capital'!H8-'Net Working Capital'!H7 -> 12019 | G20: ='Net Working Capital'!I8-'Net Working Capital'!I7 -> 4331.9669 | H20: ='Net Working Capital'!J8-'Net Working Capital'!J7 -> 11546.754 | I20: ='Net Working Capital'!K8-'Net Working Capital'!K7 -> 11844.368 | ... K20: ='Net Working Capital'!M8-'Net Working Capital'!M7 -> 12463.241
A21: Current Libility | B21: ='Net Working Capital'!D11+'Net Working Capital'!D12 -> 5658.6 | C21: ='Net Working Capital'!E11+'Net Working Capital'!E12 -> 6142.1 | D21: ='Net Working Capital'!F11+'Net Working Capital'!F12 -> 4801 | E21: ='Net Working Capital'!G11+'Net Working Capital'!G12 -> 5345 | F21: ='Net Working Capital'!H11+'Net Working Capital'!H12 -> 6857 | G21: ='Net Working Capital'!I11+'Net Working Capital'!I12 -> 5764.701 | H21: ='Net Working Capital'!J11+'Net Working Capital'!J12 -> 5900.8105 | I21: ='Net Working Capital'!K11+'Net Working Capital'!K12 -> 6040.1568 | ... K21: ='Net Working Capital'!M11+'Net Working Capital'!M12 -> 6328.8723
A22: Unlevered Free Cash Flow (mm) | B22: =B15+(-B16)+B17-B18 -> 573.4 | C22: =C15+(-C16)+C17-C18 -> -359.5 | D22: =D15+(-D16)+D17-D18 -> -1592.4 | E22: =E15+(-E16)+E17-E18 -> 1968.6 | F22: =F15+(-F16)+F17-F18 -> 1864 | G22: =G15+(-G16)+G17-G18 -> 8113.2804 | H22: =H15+(-H16)+H17-H18 -> -5483.6167 | I22: =I15+(-I16)+I17-I18 -> 1510.7417 | ... K22: =K15+(-K16)+K17-K18 -> 1644.9295

Sheet Financial Analysis
A1: Years | B1: 2021 | C1: 2022 | D1: 2023 | E1: 2024 | F1: 2025 | G1: 2026 | H1: 2027 | I1: 2028 | J1: 2029 | K1: 2030
A2: Total revenue | B2: ='Income Statemnt'!C6 -> 30953.9 | C2: ='Income Statemnt'!D6 -> 34028.9 | D2: ='Income Statemnt'!E6 -> 37388.5 | E2: ='Income Statemnt'!F6 -> 33494 | F2: ='Income Statemnt'!G6 -> 34392 | G2: ='Income Statemnt'!H6 -> 35429.923 | H2: ='Income Statemnt'!I6 -> 36499.171 | I2: ='Income Statemnt'!J6 -> 37600.687 | ... K2: ='Income Statemnt'!L6 -> 39904.451
A3: EBIT Growth | B3: ='Income Statemnt'!C20 -> 2081.3 | C3: ='Income Statemnt'!D20 -> 3414.8 | D3: ='Income Statemnt'!E20 -> 3075 | E3: ='Income Statemnt'!F20 -> 2840 | F3: ='Income Statemnt'!G20 -> 3812 | G3: ='Income Statemnt'!H20 -> 3849.2535 | H3: ='Income Statemnt'!I20 -> 4028.9623 | I3: ='Income Statemnt'!J20 -> 4213.1375 | ... K3: ='Income Statemnt'!L20 -> 4594.8951
A4: Total cost of sales | B4: ='Income Statemnt'!C7 -> -22143.7 | C4: ='Income Statemnt'!D7 -> -23713.1 | D4: ='Income Statemnt'!E7 -> -27048.2 | E4: ='Income Statemnt'!F7 -> -23740 | F4: ='Income Statemnt'!G7 -> -23620 | G4: ='Income Statemnt'!H7 -> -24163.26 | H4: ='Income Statemnt'!I7 -> -24719.015 | I4: ='Income Statemnt'!J7 -> -25287.552 | ... K4: ='Income Statemnt'!L7 -> -26464.157
A5: Profitability Ratios
A6: Gross Profit Margin | B6: ='Income Statemnt'!C8/'Income Statemnt'!C6 -> 0.28462326 | C6: ='Income Statemnt'!D8/'Income Statemnt'!D6 -> 0.30314821 | D6: ='Income Statemnt'!E8/'Income Statemnt'!E6 -> 0.27656365 | E6: ='Income Statemnt'!F8/'Income Statemnt'!F6 -> 0.29121634 | F6: ='Income Statemnt'!G8/'Income Statemnt'!G6 -> 0.31321237 | G6: ='Income Statemnt'!H8/'Income Statemnt'!H6 -> 0.31799853 | H6: ='Income Statemnt'!I8/'Income Statemnt'!I6 -> 0.32275133 | I6: ='Income Statemnt'!J8/'Income Statemnt'!J6 -> 0.327471 | ... K6: ='Income Statemnt'!L8/'Income Statemnt'!L6 -> 0.33681191
A7: Net Profit Margin | B7: ='Income Statemnt'!C35/'Income Statemnt'!C6 -> 0.058215604 | C7: ='Income Statemnt'!D35/'Income Statemnt'!D6 -> 0.085077684 | D7: ='Income Statemnt'!E35/'Income Statemnt'!E6 -> 0.073121414 | E7: ='Income Statemnt'!F35/'Income Statemnt'!F6 -> 0.089926554 | F7: ='Income Statemnt'!G35/'Income Statemnt'!G6 -> 0.11197371
A8: Return on Equity | B8: ='Income Statemnt'!C35/'Balance sheet'!C36 -> 0.1143343 | C8: ='Income Statemnt'!D35/'Balance sheet'!D36 -> 0.18380187 | D8: ='Income Statemnt'!E35/'Balance sheet'!E36 -> 0.15584882 | E8: ='Income Statemnt'!F35/'Balance sheet'!F36 -> 0.1634558 | F8: ='Income Statemnt'!G35/'Balance sheet'!G36 -> 0.22338883
A9: Operating Margin | B9: ='Income Statemnt'!C20/'Income Statemnt'!C6 -> 0.0672387 | C9: ='Income Statemnt'!D20/'Income Statemnt'!D6 -> 0.10035 | D9: ='Income Statemnt'!E20/'Income Statemnt'!E6 -> 0.08224454 | E9: ='Income Statemnt'!F20/'Income Statemnt'!F6 -> 0.084791306 | F9: ='Income Statemnt'!G20/'Income Statemnt'!G6 -> 0.11083973
A10: Return on Equity | C10: ='Income Statemnt'!D38/((('Balance sheet'!C36-'Balance sheet'!C35)+('Balance sheet'!D36-'Balance sheet'!D35))/2) -> 0.18352267 | D10: ='Income Statemnt'!E38/((('Balance sheet'!D36-'Balance sheet'!D35)+('Balance sheet'!E36-'Balance sheet'!E35))/2) -> 0.16371273 | E10: ='Income Statemnt'!F38/((('Balance sheet'!E36-'Balance sheet'!E35)+('Balance sheet'!F36-'Balance sheet'!F35))/2) -> 0.16781478 | F10: ='Income Statemnt'!G38/((('Balance sheet'!F36-'Balance sheet'!F35)+('Balance sheet'!G36-'Balance sheet'!G35))/2) -> 0.21691444
A11: Assts Turn over | C11: ='Income Statemnt'!D6/(('Balance sheet'!D25+'Balance sheet'!C25)/2) -> 1.4490403 | D11: ='Income Statemnt'!E6/(('Balance sheet'!E25+'Balance sheet'!D25)/2) -> 1.4930854 | E11: ='Income Statemnt'!F6/(('Balance sheet'!F25+'Balance sheet'!E25)/2) -> 1.2728586 | F11: ='Income Statemnt'!G6/(('Balance sheet'!G25+'Balance sheet'!F25)/2) -> 1.2838105
A12: Adjusted EBITDA Margin | B12: =('Income Statemnt'!C20+(-'Income Statemnt'!C19))/'Income Statemnt'!C6 -> 0.072220302 | C12: =('Income Statemnt'!D16+(-'Income Statemnt'!D19))/'Income Statemnt'!D6 -> 0.1012845 | D12: =('Income Statemnt'!E16+(-'Income Statemnt'!E19))/'Income Statemnt'!E6 -> 0.084550062 | E12: =('Income Statemnt'!F16+(-'Income Statemnt'!F19))/'Income Statemnt'!F6 -> 0.084671882 | F12: =('Income Statemnt'!G16+(-'Income Statemnt'!G19))/'Income Statemnt'!G6 -> 0.11200279
A13: EBIT Margin | B13: ='Income Statemnt'!C20/'Income Statemnt'!C6 -> 0.0672387 | C13: ='Income Statemnt'!D20/'Income Statemnt'!D6 -> 0.10035 | D13: ='Income Statemnt'!E20/'Income Statemnt'!E6 -> 0.08224454 | E13: ='Income Statemnt'!F20/'Income Statemnt'!F6 -> 0.084791306 | F13: ='Income Statemnt'!G20/'Income Statemnt'!G6 -> 0.11083973
A15: Liquidity Ratios
A16: Static Liquidity
A17: Current Ratio | B17: =('Balance sheet'!C22-'Balance sheet'!C23)/'Balance sheet'!C51 -> 1.8714486 | C17: =('Balance sheet'!D22-'Balance sheet'!D23)/'Balance sheet'!D51 -> 1.6401512 | D17: =('Balance sheet'!E22-'Balance sheet'!E23)/'Balance sheet'!E51 -> 1.928265 | E17: =('Balance sheet'!F22-'Balance sheet'!F23)/'Balance sheet'!F51 -> 1.8319097 | F17: =('Balance sheet'!G22-'Balance sheet'!G23)/'Balance sheet'!G51 -> 1.5206353
A18: Quick Ratio | B18: =('Balance sheet'!C22-'Balance sheet'!C17)/'Balance sheet'!C51 -> 0.91197607 | C18: =('Balance sheet'!D22-'Balance sheet'!D17)/'Balance sheet'!D51 -> 0.68204252 | D18: =('Balance sheet'!E22-'Balance sheet'!E17)/'Balance sheet'!E51 -> 0.81842923 | E18: =('Balance sheet'!F22-'Balance sheet'!F17)/'Balance sheet'!F51 -> 0.82136893 | F18: =('Balance sheet'!G22-'Balance sheet'!G17)/'Balance sheet'!G51 -> 1.04869
A19: Cash Ratio | B19: =('Balance sheet'!C21+'Balance sheet'!C20)/'Balance sheet'!C51 -> 0.36128752 | C19: =('Balance sheet'!D21+'Balance sheet'!D20)/'Balance sheet'!D51 -> 0.15006926 | D19: =('Balance sheet'!E21+'Balance sheet'!E20)/'Balance sheet'!E51 -> 0.13001035 | E19: =('Balance sheet'!F21+'Balance sheet'!F20)/'Balance sheet'!F51 -> 0.22669405 | F19: =('Balance sheet'!G21+'Balance sheet'!G20)/'Balance sheet'!G51 -> 0.56225365
A20: Net Working Capital | B20: ='Balance sheet'!C22-'Balance sheet'!C51 -> 5214.4 | C20: ='Balance sheet'!D22-'Balance sheet'!D51 -> 4760.1 | D20: ='Balance sheet'!E22-'Balance sheet'!E51 -> 6276 | E20: ='Balance sheet'!F22-'Balance sheet'!F51 -> 6118 | F20: ='Balance sheet'!G22-'Balance sheet'!G51 -> 6462
A21: Net Working Capital-to-Revanue | B21: =B20/'Income Statemnt'!C6 -> 0.16845696 | C21: =C20/'Income Statemnt'!D6 -> 0.13988404 | D21: =D20/'Income Statemnt'!E6 -> 0.1678591 | E21: =E20/'Income Statemnt'!F6 -> 0.18265958 | F21: =F20/'Income Statemnt'!G6 -> 0.18789253
A22: Efficiency Cycles
A23: Days Inventory out standing | C23: =((('Balance sheet'!D17+'Balance sheet'!C17)/2)/-'Income Statemnt'!D7)*365 -> 99.015049 | D23: =((('Balance sheet'!E17+'Balance sheet'!D17)/2)/-'Income Statemnt'!E7)*365 -> 98.69825 | E23: =((('Balance sheet'!F17+'Balance sheet'!E17)/2)/-'Income Statemnt'!F7)*365 -> 114.74668 | F23: =((('Balance sheet'!G17+'Balance sheet'!F17)/2)/-'Income Statemnt'!G7)*365 -> 104.03659
A24: Days Sales Outstanding | B24: =('Balance sheet'!C18/'Income Statemnt'!C6)*365 -> 38.854926 | C24: =('Balance sheet'!D18/'Income Statemnt'!D6)*365 -> 42.428465 | D24: =('Balance sheet'!E18/'Income Statemnt'!E6)*365 -> 45.219252 | E24: =('Balance sheet'!F18/'Income Statemnt'!F6)*365 -> 46.608497 | F24: =('Balance sheet'!G18/'Income Statemnt'!G6)*365 -> 44.255932
A25: Days Payable Outstanding | C25: =((('Balance sheet'!D45+'Balance sheet'!C45)/2)/-'Income Statemnt'!D7)*365 -> 83.189419 | D25: =((('Balance sheet'!E45+'Balance sheet'!D45)/2)/-'Income Statemnt'!E7)*365 -> 67.814226 | E25: =((('Balance sheet'!F45+'Balance sheet'!E45)/2)/-'Income Statemnt'!F7)*365 -> 71.13195 | F25: =((('Balance sheet'!G45+'Balance sheet'!F45)/2)/-'Income Statemnt'!G7)*365 -> 86.328218
A26: Cash Conversion Cycle | C26: =C23+C24-C25 -> 58.254095 | D26: =D23+D24-D25 -> 76.103276 | E26: =E23+E24-E25 -> 90.22323 | F26: =F23+F24-F25 -> 61.964304
A28: EV/EBITDA | B28: 9.5 | C28: 7.2 | D28: 7.1 | E28: 8.6 | F28: 8.4
A31: Leverage and solvency Ratios
A32: Debt-to-Equity Ratio | B32: =('Balance sheet'!C50+'Balance sheet'!C41)/'Balance sheet'!C36 -> 0.035994366 | C32: =('Balance sheet'!D50+'Balance sheet'!D41)/'Balance sheet'!D36 -> 0.09483087 | D32: =('Balance sheet'!E50+'Balance sheet'!E41)/'Balance sheet'!E36 -> 0.11941056 | E32: =('Balance sheet'!F50+'Balance sheet'!F41)/'Balance sheet'!F36 -> 0.067406523 | F32: =('Balance sheet'!G50+'Balance sheet'!G41)/'Balance sheet'!G36 -> 0.020708858
A33: Debt to Assts Ratio | B33: =('Balance sheet'!C50+'Balance sheet'!C41)/'Balance sheet'!C25 -> 0.024783424 | C33: =('Balance sheet'!D50+'Balance sheet'!D41)/'Balance sheet'!D25 -> 0.062037945 | D33: =('Balance sheet'!E50+'Balance sheet'!E41)/'Balance sheet'!E25 -> 0.080549894 | E33: =('Balance sheet'!F50+'Balance sheet'!F41)/'Balance sheet'!F25 -> 0.046655148 | F33: =('Balance sheet'!G50+'Balance sheet'!G41)/'Balance sheet'!G25 -> 0.013244296
A34: Interest Coverage Ratio | B34: ='Income Statemnt'!C20/(-'Income Statemnt'!C23) -> 36.514035 | C34: ='Income Statemnt'!D20/-'Income Statemnt'!D23 -> 38.325477 | D34: ='Income Statemnt'!E20/-'Income Statemnt'!E23 -> 11.478163 | E34: ='Income Statemnt'!F20/-'Income Statemnt'!F23 -> 9.1909385 | F34: ='Income Statemnt'!G20/-'Income Statemnt'!G23 -> 52.944444
A35: Debt to service coverage Ratio | B35: ='Cash flow'!C7/((-'Cash flow'!C10)+(-'Cash flow'!C35)+(-'Cash flow'!C41)) -> 13.213498 | C35: ='Cash flow'!D7/((-'Cash flow'!D10)+(-'Cash flow'!D35)+(-'Cash flow'!D41)) -> 9.4367089 | D35: ='Cash flow'!E7/((-'Cash flow'!E10)+(-'Cash flow'!E35)+(-'Cash flow'!E41)) -> 1.4694499 | E35: ='Cash flow'!F7/((-'Cash flow'!F10)+(-'Cash flow'!F35)+(-'Cash flow'!F41)) -> 3.6615866 | F35: ='Cash flow'!G7/((-'Cash flow'!G10)+(-'Cash flow'!G35)+(-'Cash flow'!G41)) -> 4.689314
A36: Equity Multiplier | C36: ='Balance sheet'!D25/(('Balance sheet'!D36+'Balance sheet'!C36)/2) -> 1.528129 | D36: ='Balance sheet'!E25/(('Balance sheet'!E36+'Balance sheet'!D36)/2) -> 1.5621809 | E36: ='Balance sheet'!F25/(('Balance sheet'!F36+'Balance sheet'!E36)/2) -> 1.4803303 | F36: ='Balance sheet'!G25/(('Balance sheet'!G36+'Balance sheet'!F36)/2) -> 1.5115236
A37: Growth metrics
A38: Revanue Growth Rate | C38: =('Income Statemnt'!D6-'Income Statemnt'!C6)/'Income Statemnt'!C6 -> 0.099341278 | D38: =('Income Statemnt'!E6-'Income Statemnt'!D6)/'Income Statemnt'!D6 -> 0.098727846 | E38: =('Income Statemnt'!F6-'Income Statemnt'!E6)/'Income Statemnt'!E6 -> -0.10416304 | F38: =('Income Statemnt'!G6-'Income Statemnt'!F6)/'Income Statemnt'!F6 -> 0.026810772
A39: EBIT Growth rate | C39: =('Income Statemnt'!D16-'Income Statemnt'!C16)/'Income Statemnt'!C16 -> 0.53464549 | D39: =('Income Statemnt'!E16-'Income Statemnt'!D16)/'Income Statemnt'!D16 -> -0.091147579 | E39: =('Income Statemnt'!F16-'Income Statemnt'!E16)/'Income Statemnt'!E16 -> -0.089801155 | F39: =('Income Statemnt'!G16-'Income Statemnt'!F16)/'Income Statemnt'!F16 -> 0.35024665
A40: Net income Growth rate | C40: =('Income Statemnt'!D35-'Income Statemnt'!C35)/'Income Statemnt'!C35 -> 0.60660377 | D40: =('Income Statemnt'!E35-'Income Statemnt'!D35)/'Income Statemnt'!D35 -> -0.055680287 | E40: =('Income Statemnt'!F35-'Income Statemnt'!E35)/'Income Statemnt'!E35 -> 0.10172281 | F40: =('Income Statemnt'!G35-'Income Statemnt'!F35)/'Income Statemnt'!F35 -> 0.27855246
A41: Earning Per share | B41: ='Income Statemnt'!C43 -> 1050 | C41: ='Income Statemnt'!D43 -> 1738 | D41: ='Income Statemnt'!E43 -> 1700 | E41: ='Income Statemnt'!F43 -> 1888 | F41: ='Income Statemnt'!G43 -> 2449
A42: EPS growth | C42: =(C41/B41)-1 -> 0.6552381 | D42: =(D41/C41)-1 -> -0.021864212 | E42: =(E41/D41)-1 -> 0.11058824 | F42: =(F41/E41)-1 -> 0.29713983
A43: Free Cash Flow | B43: ='Cash flow'!C15-(-'Cash flow'!C18) -> 599.3 | C43: ='Cash flow'!D15-(-'Cash flow'!D18) -> -357.2 | D43: ='Cash flow'!E15-(-'Cash flow'!E18) -> -842.4 | E43: ='Cash flow'!F15-(-'Cash flow'!F18) -> 1977.9 | F43: ='Cash flow'!G15-(-'Cash flow'!G18) -> 1091
A44: Free Cash Flow Growth | C44: =(C43/B43)-1 -> -1.5960287 | D44: =(D43/C43)-1 -> 1.3583427 | E44: =(-E43-D43)/D43 -> 1.3479345 | F44: =(-F43-E43)/E43 -> -1.5515951
...

Sheet Data & Calculations>>

Sheet Income Statemnt
A1: Tiger Brands Limited – Consolidated Income Statement
A2: Five-year period: FY2021 – FY2025 | Year ended 30 September | Amounts in R'million
A3: Actual | H3: Forecasted
A4: (R'million) | C4: 2021 | D4: 2022 | E4: 2023 | F4: 2024 | G4: 2025 | H4: 2026E | I4: 2027E | J4: 2028E | K4: 2029E | L4: 2030E
A5: Revenue | N5: Assumptions | O5: 2021 | P5: 2022 | Q5: 2023 | R5: 2024 | S5: 2025 | T5: Average(AAGR)
A6: Total revenue | C6: 30953.9 | D6: 34028.9 | E6: 37388.5 | F6: 33494 | G6: 34392 | H6: =G6*(1+$T6) -> 35429.923 | I6: =H6*(1+$T6) -> 36499.171 | J6: =I6*(1+$T6) -> 37600.687 | K6: =J6*(1+$T6) -> 38735.446 | L6: =K6*(1+$T6) -> 39904.451 | N6: Revanue | P6: =(D6/C6)-1 -> 0.099341278 | Q6: =(E6/D6)-1 -> 0.098727846 | R6: =(F6/E6)-1 -> -0.10416304 | S6: =(G6/F6)-1 -> 0.026810772 | T6: =AVERAGE(O6:S6) -> 0.030179213 | V6: PPI Rate | W6: =2.3% -> 0.023
A7: Total cost of sales | C7: -22143.7 | D7: -23713.1 | E7: -27048.2 | F7: -23740 | G7: -23620 | H7: =G7*(1+$W$6) -> -24163.26 | I7: =H7*(1+$W$6) -> -24719.015 | J7: =I7*(1+$W$6) -> -25287.552 | K7: =J7*(1+$W$6) -> -25869.166 | L7: =K7*(1+$W$6) -> -26464.157 | N7: COGS as a % of revanue | O7: =-C7/C6 -> 0.71537674 | P7: =-D7/D6 -> 0.69685179 | Q7: =-E7/E6 -> 0.72343635 | R7: =-F7/F6 -> 0.70878366 | S7: =-G7/G6 -> 0.68678763 | T7: =AVERAGE(O7:S7) -> 0.70624723 | V7: Volume Growth Rate | W7: =((1+T6)/(1+W6))-1 -> 0.0070178035
A8: Gross profit | C8: =C6+C7 -> 8810.2 | D8: =D6+D7 -> 10315.8 | E8: =E6+E7 -> 10340.3 | F8: =F6+F7 -> 9754 | G8: =G6+G7 -> 10772 | H8: =H6+H7 -> 11266.663 | I8: =I6+I7 -> 11780.156 | J8: =J6+J7 -> 12313.135 | ... L8: =L6+L7 -> 13440.295 | N8: Operating Expense | O8: =-C10/C6 -> 0.21407319 | P8: =-D10/D6 -> 0.20839345 | Q8: =-E10/E6 -> 0.19923238 | R8: =-F10/F6 -> 0.20988834 | S8: =-G10/G6 -> 0.20638521 | T8: =AVERAGE(O8:S8) -> 0.20759451
A9: Operating Expenses | N9: Income tax | O9: =-C32/C29 -> 0.24878049 | P9: =-D32/D29 -> 0.26043529 | Q9: =-E32/E29 -> 0.2301042 | R9: =-F32/F29 -> 0.20733104 | S9: =-G32/G29 -> 0.31834832 | T9: =AVERAGE(O9:S9) -> 0.25299987
A10: Total Expenses | C10: =C11+C12+C13 -> -6626.4 | D10: =D11+D12+D13 -> -7091.4 | E10: =E11+E12+E13 -> -7449 | F10: =F11+F12+F13 -> -7030 | G10: =G11+G12+G13 -> -7098 | H10: =H11+H12+H13 -> -7417.41 | I10: =I11+I12+I13 -> -7751.1934 | J10: =J11+J12+J13 -> -8099.9972 | ... L10: =L11+L12+L13 -> -8845.3994 | N10: Interest(Finance Cost) | O10: =-C23/(('Balance sheet'!C50+'Balance sheet'!C41)/2) -> 0.20095188 | P10: =-D23/(('Balance sheet'!D50+'Balance sheet'!D41)/2) -> 0.11930106 | Q10: =-E23/(('Balance sheet'!E50+'Balance sheet'!E41)/2) -> 0.25578842 | R10: =-F23/(('Balance sheet'!F50+'Balance sheet'!F41)/2) -> 0.49754448 | S10: =-G23/(('Balance sheet'!G50+'Balance sheet'!G41)/2) -> 0.40336134 | T10: =AVERAGE(P10:S10) -> 0.31899883 | V10: CPI Rate | W10: 0.045
A11: Sales and distribution expenses | C11: -4047.8 | D11: -4350.3 | E11: -4702 | F11: -4377 | G11: -4386 | H11: =G11*(1+$W$10) -> -4583.37 | I11: =H11*(1+$W$10) -> -4789.6216 | J11: =I11*(1+$W$10) -> -5005.1546 | K11: =J11*(1+$W$10) -> -5230.3866 | L11: =K11*(1+$W$10) -> -5465.754 | N11: Interst (Finance income) | O11: ='Income Statemnt'!C24/'Balance sheet'!C21 -> 0.0012952169 | P11: ='Income Statemnt'!D24/'Balance sheet'!D21 -> 0.012725155 | Q11: ='Income Statemnt'!E24/'Balance sheet'!E21 -> 0.03542654 | R11: ='Income Statemnt'!F24/'Balance sheet'!F21 -> 0.013538462 | S11: ='Income Statemnt'!G24/'Balance sheet'!G21 -> 0.044639948 | T11: =AVERAGE(O11:S11) -> 0.021525064
A12: Marketing expenses | C12: -905.5 | D12: -906.9 | E12: -969.1 | F12: -805 | G12: -900 | H12: =G12*(1+$W$10) -> -940.5 | I12: =H12*(1+$W$10) -> -982.8225 | J12: =I12*(1+$W$10) -> -1027.0495 | K12: =J12*(1+$W$10) -> -1073.2667 | L12: =K12*(1+$W$10) -> -1121.5637 | N12: Income from associate company% of revanue | O12: =(C27/C6) -> 0.011174682 | P12: =(D27/D6) -> 0.014046884 | Q12: =(E27/E6) -> 0.018631397 | R12: =(F27/F6) -> 0.021615812 | S12: =(G27/G6) -> 0.010932775 | T12: =AVERAGE(O12:S12) -> 0.01528031
A13: Other operating expenses | C13: -1673.1 | D13: -1834.2 | E13: -1777.9 | F13: -1848 | G13: -1812 | H13: =G13*(1+$W$10) -> -1893.54 | I13: =H13*(1+$W$10) -> -1978.7493 | J13: =I13*(1+$W$10) -> -2067.793 | K13: =J13*(1+$W$10) -> -2160.8437 | L13: =K13*(1+$W$10) -> -2258.0817 | N13: INvestment income % of revanue | O13: =C26/C6 -> 0.0005750487 | P13: =D26/D6 -> 0.00066708004 | Q13: =E26/E6 -> 0.00048143146 | R13: =F26/F6 -> 0.00065683406 | S13: =G26/G6 -> 0.00055245406 | T13: =AVERAGE(O13:S13) -> 0.00058656966 | V13: Corporate Tax Rate | W13: 0.27
A14: Sundry income | C14: 219 | D14: 218.8 | E14: 167.9 | F14: 94 | G14: 157 | H14: =G14*(1+$W$10) -> 164.065 | I14: =H14*(1+$W$10) -> 171.44792 | J14: =I14*(1+$W$10) -> 179.16308 | K14: =J14*(1+$W$10) -> 187.22542 | L14: =K14*(1+$W$10) -> 195.65056
A15: Expected credit loss (raised)/reversed | C15: -51.7 | D15: -12.5 | E15: 59 | F15: 20 | G15: 1 | H15: 1 | I15: 1 | J15: 1 | K15: 1 | L15: 1
A16: Operating income before impairments | C16: 2235.5 | D16: 3430.7 | E16: 3118 | F16: 2838 | G16: 3832
A18: Non-Operating Items
A19: Impairments and fair value (loss)/gain | C19: -154.2 | D19: -15.9 | E19: -43.2 | F19: 2 | G19: -20
A20: Operating income after impairments(EBIT) | C20: 2081.3 | D20: 3414.8 | E20: 3075 | F20: 2840 | G20: 3812 | H20: =H8+H10 -> 3849.2535 | I20: =I8+I10 -> 4028.9623 | J20: =J8+J10 -> 4213.1375 | K20: =K8+K10 -> 4401.783 | L20: =L8+L10 -> 4594.8951
A21: Non-operational items | C21: 27.2 | D21: 28.3 | E21: 33 | F21: 242 | G21: 631
A22: Profit including non-operational items | C22: =C20+C21 -> 2108.5 | D22: =D20+D21 -> 3443.1 | E22: =E20+E21 -> 3108 | F22: 3082 | G22: 4443 | H22: =H20+H21 -> 3849.2535 | I22: =I20+I21 -> 4028.9623 | J22: =J20+J21 -> 4213.1375 | K22: =K20+K21 -> 4401.783 | L22: =L20+L21 -> 4594.8951
A23: Finance costs | C23: -57 | D23: -89.1 | E23: -267.9 | F23: -309 | G23: -72 | H23: =-(('Balance sheet'!H50+'Balance sheet'!H41)/2)*'Income Statemnt'!$T10 -> -56.941291 | I23: =-(('Balance sheet'!I50+'Balance sheet'!I41)/2)*'Income Statemnt'!$T10 -> -56.941291 | J23: =-(('Balance sheet'!J50+'Balance sheet'!J41)/2)*'Income Statemnt'!$T10 -> -56.941291 | K23: =-(('Balance sheet'!K50+'Balance sheet'!K41)/2)*'Income Statemnt'!$T10 -> -56.941291 | L23: =-(('Balance sheet'!L50+'Balance sheet'!L41)/2)*'Income Statemnt'!$T10 -> -56.941291
A24: Finance income | C24: 2.8 | D24: 14.2 | E24: 29.9 | F24: 22 | G24: 137 | H24: ='Balance sheet'!H21*'Income Statemnt'!$T11 -> 126.91178 | I24: ='Balance sheet'!I21*'Income Statemnt'!$T11 -> 187.74161 | J24: ='Balance sheet'!J21*'Income Statemnt'!$T11 -> 262.82103 | K24: ='Balance sheet'!K21*'Income Statemnt'!$T11 -> 352.58055 | L24: ='Balance sheet'!L21*'Income Statemnt'!$T11 -> 457.62287
A25: Foreign exchange gain/(loss) | C25: -8.7 | D25: 45.7 | E25: -33.6 | F25: -49 | G25: 107
A26: Income from associated companies | C26: 17.8 | D26: 22.7 | E26: 18 | F26: 22 | G26: 19 | H26: =G26 -> 19 | I26: =H26 -> 19 | J26: =J6*$T13 -> 22.055422 | K26: =K6*$T13 -> 22.721038 | L26: =L6*$T13 -> 23.406741
A27: Income from associated companies | C27: 345.9 | D27: 478 | E27: 696.6 | F27: 724 | G27: 376 | H27: =H6*$T12 -> 541.38022 | I27: =I6*$T12 -> 557.71864 | J27: =J6*$T12 -> 574.55015 | K27: =K6*$T12 -> 591.88963 | L27: =L6*$T12 -> 609.75239
A28: Profit on disposal of associate | C28: 0 | D28: 0 | E28: 0 | F28: 0 | G28: 996
A29: Profit before taxation | C29: 2398.5 | D29: 3914.6 | E29: 3551 | F29: 3492 | G29: 6006 | H29: =H22+H23+H24+H26+H27 -> 4479.6042 | I29: =I22+I23+I24+I26+I27 -> 4736.4812 | J29: =J22+J23+J24+J26+J27 -> 5015.6228 | K29: =K22+K23+K24+K26+K27 -> 5312.033 | L29: =L22+L23+L24+L26+L27 -> 5628.7358
A31: Taxation & Profit
A32: Taxation | C32: -596.7 | D32: -1019.5 | E32: -817.1 | F32: -724 | G32: -1912 | H32: =-H29*$W$13 -> -1209.4931 | I32: =-I29*$W$13 -> -1278.8499 | J32: =-J29*$W$13 -> -1354.2182 | K32: =-K29*$W$13 -> -1434.2489 | L32: =-L29*$W$13 -> -1519.7587
A33: Profit for year (continuing ops) | C33: 1801.8 | D33: 2895.1 | E33: 2733.9 | F33: 2768 | G33: 4094 | H33: =H29+H32 -> 3270.1111 | I33: =I29+I32 -> 3457.6313 | J33: =J29+J32 -> 3661.4046 | K33: =K29+K32 -> 3877.7841 | L33: =L29+L32 -> 4108.9772
A34: (Loss)/profit from discontinued ops | C34: 0 | D34: 0 | E34: 0 | F34: 244 | G34: -243
A35: Profit for the year | C35: 1802 | D35: 2895.1 | E35: 2733.9 | F35: 3012 | G35: 3851 | H35: =H33 -> 3270.1111 | I35: =I33 -> 3457.6313 | J35: =J33 -> 3661.4046 | K35: =K33 -> 3877.7841 | L35: =L33 -> 4108.9772
A37: Attributable to
A38: Owners of the parent | C38: 1773 | D38: 2865 | E38: 2697.2 | F38: 2983 | G38: 3817
A39: Non-controlling interests | C39: 29 | D39: 30 | E39: 36.7 | F39: 29 | G39: 34
C40: ='Income Statemnt'!D21-'Income Statemnt'!C21/'Income Statemnt'!C21 -> 27.3
A41: Per Share Data (cents)
A42: Basic earnings per share(Cents) | C42: 1065 | D42: 1762 | E42: 1725 | F42: 1914 | G42: 2482
A43: Diluted basic EPS(cents) | C43: 1050 | D43: 1738 | E43: 1700 | F43: 1888 | G43: 2449
...

Sheet Cash flow
A1: Tiger Brands Limited – Consolidated Statement of Cash Flows
A2: Five-year period: FY2021 – FY2025 | Year ended 30 September | Amounts in R'million | H2: Forecasted | N2: Assumptions
A3: (R'million) | B3: Notes | C3: 2021 | D3: 2022 | E3: 2023 | F3: 2024 | G3: 2025 | H3: 2026E | I3: 2027E | J3: 2028E | K3: 2029E | L3: 2030E | O3: 2021 | P3: 2022 | Q3: 2023 | R3: 2024 | S3: 2025 | T3: Average | X3: 2026 | Y3: 2027 | Z3: 2028 | AA3: 2029 | AB3: 2030
A4: OPERATING ACTIVITIES | N4: Cash operating profit | P4: =(D5/C5)-1 -> 0.0015242115 | Q4: =(E5/D5)-1 -> -0.0015218918 | R4: =(F5/E5)-1 -> 0.11771603 | S4: =(G5/F5)-1 -> 0.24263086 | T4: =AVERAGE(P4:S4) -> 0.090087302 | W4: Net increase/decrease in cash | X4: =H15+H32+H43 -> 1438.92 | Y4: =I15+I32+I43 -> 2052.5934 | Z4: =J15+J32+J43 -> 2670.7778 | AA4: =K15+K32+K43 -> 3306.9202 | AB4: =L15+L32+L43 -> 3969.7505
A5: Cash operating profit | B5: 10.1 | C5: 4264.5 | D5: 4271 | E5: 4264.5 | F5: 4766.5 | G5: 5923 | H5: =G5*(1+$T4) -> 6456.5871 | I5: =H5*(1+$T4) -> 7038.2436 | J5: =I5*(1+$T4) -> 7672.3 | K5: =J5*(1+$T4) -> 8363.4768 | L5: =K5*(1+$T4) -> 9116.9198 | N5: Working capital changes % oF Revanue | O5: =C6/'Income Statemnt'!C6 -> 0.0035472105 | P5: =D6/'Income Statemnt'!D6 -> -0.046642707 | Q5: =E6/'Income Statemnt'!E6 -> -0.04175883 | R5: =F6/'Income Statemnt'!F6 -> 0.021956171 | S5: =G6/'Income Statemnt'!G6 -> 0.034484764 | T5: =AVERAGE(O5:S5) -> -0.0056826781
A6: Working capital changes | B6: 10.2 | C6: 109.8 | D6: -1587.2 | E6: -1561.3 | F6: 735.4 | G6: 1186 | H6: ='Income Statemnt'!H6*'Cash flow'!$T5 -> -201.33685 | I6: ='Income Statemnt'!I6*'Cash flow'!$T5 -> -207.41304 | J6: ='Income Statemnt'!J6*'Cash flow'!$T5 -> -213.6726 | K6: ='Income Statemnt'!K6*'Cash flow'!$T5 -> -220.12107 | L6: ='Income Statemnt'!L6*'Cash flow'!$T5 -> -226.76415
A7: Cash generated from operations | C7: 3954.8 | D7: 2683.8 | E7: 2703.2 | F7: 5501.9 | G7: 7109 | H7: =H5+H6 -> 6255.2502 | I7: =I5+I6 -> 6830.8306 | J7: =J5+J6 -> 7458.6274 | K7: =K5+K6 -> 8143.3557 | L7: =L5+L6 -> 8890.1557 | N7: finance cost paid | O7: =C10/('Balance sheet'!C41+'Balance sheet'!C50) -> -0.12057113 | P7: =D10/('Balance sheet'!D41+'Balance sheet'!D50) -> -0.070830823 | Q7: =E10/('Balance sheet'!E41+'Balance sheet'!E50) -> -0.12230868 | R7: =F10/('Balance sheet'!F41+'Balance sheet'!F50) -> -0.25360277 | S7: =G10/('Balance sheet'!G41+'Balance sheet'!G50) -> -0.20168067 | T7: =AVERAGE(P7:S7) -> -0.16210574
A8: Finance income received | C8: 30.6 | D8: 44.7 | E8: 47.9 | F8: 42 | G8: 140 | N8: taxation paid | O8: =C12/C7 -> -0.18595125 | P8: =D12/D7 -> -0.35826068 | Q8: =E12/E7 -> -0.298905 | R8: =F12/F7 -> 0.15785456 | S8: =G12/G7 -> -0.19524546 | T8: =AVERAGE(O8:S8) -> -0.17610157
A9: Income from Investments received | G9: 19 | N9: dividends paid | O9: =C14/C13 -> -0.51085836 | P9: =D14/D13 -> -0.68194786 | Q9: =E14/E13 -> -0.80858325 | R9: =F14/F13 -> -0.35758487 | S9: =G14/G13 -> -0.60878518 | T9: =AVERAGE(O9:S9) -> -0.5935519
A10: Finance costs paid | C10: -68.4 | D10: -105.8 | E10: -256.2 | F10: -315 | G10: -72 | H10: =('Balance sheet'!H41+'Balance sheet'!H50)*$T7 -> -57.871748 | I10: =('Balance sheet'!I41+'Balance sheet'!I50)*$T7 -> -57.871748 | J10: =('Balance sheet'!J41+'Balance sheet'!J50)*$T7 -> -57.871748 | K10: =('Balance sheet'!K41+'Balance sheet'!K50)*$T7 -> -57.871748 | L10: =('Balance sheet'!L41+'Balance sheet'!L50)*$T7 -> -57.871748 | N10: Purchase of PP&E and Intagible assts | P10: =(D18/C18)-1 -> -0.009568906 | Q10: =(E18/D18)-1 -> 0.20776892 | R10: =(F18/E18)-1 -> -0.1997361 | S10: =(G18/F18)-1 -> 0.22526793 | T10: =AVERAGE(P10:S10) -> 0.055932961
A11: Dividends received from assoc/subs | C11: 115.4 | D11: 372 | E11: 247.1 | F11: 229 | G11: 20 | N11: Effect of exchange rate changes | P11: =(D49/C49)-1 -> -1.7014695 | Q11: =(E49/D49)-1 -> -1.4443219 | R11: =(F49/E49)-1 -> 0.72952854 | S11: =(G49/F49)-1 -> -0.59827834 | T11: =AVERAGE(O11:S11) -> -0.7536353
A12: Taxation paid | B12: 10.3 | C12: -735.4 | D12: -961.5 | E12: -808 | F12: 868.5 | G12: -1388 | H12: =G12*(1+$T8) -> -1143.571 | I12: =H12*(1+$T8) -> -942.18638 | J12: =I12*(1+$T8) -> -776.26588 | K12: =J12*(1+$T8) -> -639.56424 | L12: =K12*(1+$T8) -> -526.93598 | N12: Closing cash and cash equivalent | P12: =(D52/C52)-1 -> -0.48376353 | Q12: =(E52/D52)-1 -> -0.3047491 | R12: =(F52/E52)-1 -> 0.67869571 | S12: =(G52/F52)-1 -> 1.4775432 | T12: =AVERAGE(P12:S12) -> 0.34193157
A13: Cash available from operations | C13: 3297 | D13: 2033 | E13: 1934 | F13: 4589.4 | G13: 5828 | H13: =H7+H8+H9+H10+H11+H12 -> 5053.8075 | I13: =I7+I8+I9+I10+I11+I12 -> 5830.7724 | J13: =J7+J8+J9+J10+J11+J12 -> 6624.4898 | K13: =K7+K8+K9+K10+K11+K12 -> 7445.9197 | L13: =L7+L8+L9+L10+L11+L12 -> 8305.348 | N13: Cash conversion ratio | O13: =C8/'Income Statemnt'!C24 -> 10.928571 | P13: =D8/'Income Statemnt'!D24 -> 3.1478873 | Q13: =E8/'Income Statemnt'!E24 -> 1.6020067 | R13: =F8/'Income Statemnt'!F24 -> 1.9090909 | S13: =G8/'Income Statemnt'!G24 -> 1.0218978 | T13: =AVERAGE(O13:S13) -> 3.7218908
A14: Dividends paid | B14: 10.4 | C14: -1684.3 | D14: -1386.4 | E14: -1563.8 | F14: -1641.1 | G14: -3548 | H14: ='Income Statemnt'!H35*'Cash flow'!$T15 -> -2257.5135 | I14: ='Income Statemnt'!I35*'Cash flow'!$T15 -> -2386.9676 | J14: ='Income Statemnt'!J35*'Cash flow'!$T15 -> -2527.6421 | K14: ='Income Statemnt'!K35*'Cash flow'!$T15 -> -2677.0191 | L14: ='Income Statemnt'!L35*'Cash flow'!$T15 -> -2836.6227 | N14: Capex as % of revanue | O14: =-C18/'Income Statemnt'!C6 -> 0.0327487 | P14: =-D18/'Income Statemnt'!D6 -> 0.029504333 | Q14: =-E18/'Income Statemnt'!E6 -> 0.032432432 | R14: =-F18/'Income Statemnt'!F6 -> 0.028972353 | S14: =-G18/'Income Statemnt'!G6 -> 0.034571993 | T14: =AVERAGE(O14:S14) -> 0.031645963
A15: Net cash from operating activities | C15: 1613 | D15: 646.8 | E15: 370.2 | F15: 2948.3 | G15: 2280 | H15: =H13+H14 -> 2796.294 | I15: =I13+I14 -> 3443.8048 | J15: =J13+J14 -> 4096.8477 | K15: =K13+K14 -> 4768.9006 | L15: =L13+L14 -> 5468.7253 | N15: Divident Pay out Ratio | O15: =C14/'Income Statemnt'!C35 -> -0.93468368 | P15: =D14/'Income Statemnt'!D35 -> -0.4788781 | Q15: =E14/'Income Statemnt'!E35 -> -0.57200337 | R15: =F14/'Income Statemnt'!F35 -> -0.54485392 | S15: =G14/'Income Statemnt'!G35 -> -0.92131914 | T15: =AVERAGE(O15:S15) -> -0.69034764
C16: =C13-C14 -> 4981.3 | N16: Lease repayment Libilities | T16: =(C35+D35+E35+F35+G35)/5 -> -236.16
A17: INVESTING ACTIVITIES
A18: Purchase of PP&E and intagibles | B18: 10.5 | C18: -1013.7 | D18: -1004 | E18: -1212.6 | F18: -970.4 | G18: -1189 | H18: =-'Income Statemnt'!H6*'Cash flow'!$T$14 -> -1121.214 | I18: =-'Income Statemnt'!I6*'Cash flow'!$T$14 -> -1155.0514 | J18: =-'Income Statemnt'!J6*'Cash flow'!$T$14 -> -1189.9099 | K18: =-'Income Statemnt'!K6*'Cash flow'!$T$14 -> -1225.8205 | L18: =-'Income Statemnt'!L6*'Cash flow'!$T$14 -> -1262.8148
A19: Proceeds on disposal of PP&E and intigible assts | B19: 10.5 | C19: 86 | D19: 3.1 | E19: 26.8 | F19: 40.3 | G19: 37
A20: Funds held in escrow | C20: -196.1 | D20: -46.2 | E20: 39.2 | F20: 2.2 | G20: -2
A21: Proceeds on disposal of Baby Wellbeing | G21: 575
A22: Proceeds on disposal Carozzi | G22: 4383
A23: Investment in dual currency deposits | G23: -4383
A24: Proceed from dual currency deposits | G24: 2584
A25: Proceeds on disposal of investments | C25: 140.2 | D25: 2.4 | E25: 2.6 | F25: 2.6 | G25: 27
A26: proceeds from disposal of intangible assts | E26: 0 | F26: 262.5 | G26: 4383
A27: Purchase of investments | D27: -5.4 | E27: 0 | F27: -1.9 | G27: 0
A28: Cash disposal division | C28: 153
A29: loans acdived/ received | C29: 26
A30: insurence proceeds on PPE received relating to civil unrest | D30: 28.3
A31: investment in unit trust | G31: -54
A32: Net cash from investing activities | C32: 855.8 | D32: -1040.8 | E32: -1144 | F32: -664.7 | G32: 2017 | H32: =H18 -> -1121.214 | I32: =I18 -> -1155.0514 | J32: =J18 -> -1189.9099 | K32: =K18 -> -1225.8205 | L32: =L18 -> -1262.8148
A34: FINANCING ACTIVITIES
A35: Repayment of lease liabilities | B35: 8.1 | C35: -216.7 | D35: -178.6 | E35: -203.4 | F35: -222.1 | G35: -360 | H35: =$T16 -> -236.16 | I35: =$T16 -> -236.16 | J35: =$T16 -> -236.16 | K35: =$T16 -> -236.16 | L35: =$T16 -> -236.16
A36: Black Managers Trust(BMT) Shars excersed | C36: 3.5 | D36: 5 | E36: 4.1 | F36: 7.1 | G36: 6
A37: Repurchase of shares of shres for the equity-settled scheme | C37: -17.9 | D37: -1 | E37: -38 | F37: -102.8
A38: Repurchase of Tiger Brands shares | B38: 7.2 | D38: -1453.1 | E38: 0 | F38: -215.5 | G38: -1523
A39: Long-term borrowings raised/(paid) | B39: 8.2 | D39: 0 | E39: 1002.1 | F39: -1002.1 | G39: 0
A40: Short-term borrowings raised | B40: 8.3 | D40: 972.8 | E40: 1103.9 | F40: 813.1 | G40: 539
A41: Short-term borrowings paid | B41: 8.3 | C41: -14.2 | D41: 0 | E41: -1380 | F41: -965.5 | G41: -1084
...

Sheet Balance sheet
A1: Tiger Brands Limited – Consolidated Statement of Financial Position
A2: Five-year period: FY2021 – FY2025 | Year ended 30 September | Amounts in R'million
A3: Actual | H3: Forecasted
A4: (R'million) | B4: Notes | C4: 2021 | D4: 2022 | E4: 2023 | F4: 2024 | G4: 2025 | H4: 2026 | I4: 2027 | J4: 2028 | K4: 2029 | L4: 2030 | O4: Assumpions | P4: 2021 | Q4: 2022 | R4: 2023 | S4: 2024 | T4: 2025 | U4: Average (AAG)
A5: NON-CURRENT ASSETS | O5: Property Plant and equipment | P5: =C6/'Income Statemnt'!C6 -> 0.17999994 | Q5: =D6/'Income Statemnt'!D6 -> 0.17094881 | R5: =E6/'Income Statemnt'!E6 -> 0.15622451 | S5: =F6/'Income Statemnt'!F6 -> 0.17262793 | T5: =G6/'Income Statemnt'!G6 -> 0.17288904 | U5: =AVERAGE(Q5:T5) -> 0.16817257
A6: Property. plant and equipment | B6: 4.1 | C6: 5571.7 | D6: 5817.2 | E6: 5841 | F6: 5782 | G6: 5946 | H6: =G6*(1+$U$5) -> 6945.9541 | I6: =H6*(1+$U$5) -> 8114.0731 | J6: =I6*(1+$U$5) -> 9478.6377 | K6: =J6*(1+$U$5) -> 11072.685 | L6: =K6*(1+$U$5) -> 12934.806 | O6: Intangible Assts | Q6: =(D9/C9)-1 -> 0.0019361778 | R6: =(E9/D9)-1 -> 0.0027197252 | S6: =(F9/E9)-1 -> -0.022840828 | T6: =(G9/F9)-1 -> -0.090577064 | U6: =AVERAGE(Q6:T6) -> -0.027190497
A7: Right-of-use assets | B7: 4.2 | E7: 349 | F7: 414 | G7: 315 | O7: Inventories as % of Cost of sales | P7: =-C17/'Income Statemnt'!C7 -> 0.25926562 | Q7: =-D17/'Income Statemnt'!D7 -> 0.30044153 | R7: =-E17/'Income Statemnt'!E7 -> 0.27741587 | S7: =-F17/'Income Statemnt'!F7 -> 0.31267481 | T7: =-G17/'Income Statemnt'!G7 -> 0.25580017 | U7: =AVERAGE(Q7:T7) -> 0.2865831
A8: Goodwill | B8: 5.1 | C8: 1645.7 | D8: 1645.2 | E8: 1660 | F8: 1652 | G8: 1612 | O8: Trade and other receivables as % of revanue | P8: =C18/'Income Statemnt'!C6 -> 0.10645185 | Q8: =D18/'Income Statemnt'!D6 -> 0.11624237 | R8: =E18/'Income Statemnt'!E6 -> 0.12388836 | S8: =F18/'Income Statemnt'!F6 -> 0.12769451 | T8: =G18/'Income Statemnt'!G6 -> 0.12124913 | U8: =AVERAGE(Q8:T8) -> 0.12226859
A9: Intangible assets | B9: 5.1 | C9: 1394.5 | D9: 1397.2 | E9: 1401 | F9: 1369 | G9: 1245 | H9: =G9*(1+$U6) -> 1211.1478 | I9: =H9*(1+$U6) -> 1178.2161 | J9: =I9*(1+$U6) -> 1146.1798 | K9: =J9*(1+$U6) -> 1115.0146 | L9: =K9*(1+$U6) -> 1084.6968 | O9: Trade and other payables as % of cost of sales | P9: =-C45/'Income Statemnt'!C7 -> 0.23173634 | Q9: =-D45/'Income Statemnt'!D7 -> 0.23943306 | R9: =-E45/'Income Statemnt'!E7 -> 0.16167434 | S9: =-F45/'Income Statemnt'!F7 -> 0.20556024 | T9: =-G45/'Income Statemnt'!G7 -> 0.26642676 | U9: =AVERAGE(Q9:T9) -> 0.2182736
A10: Investments in associated cos. | B10: 5.2 | C10: 2400.7 | D10: 2421.2 | E10: 3092 | F10: 3347 | G10: 313 | O10: Employee-related accruals | P10: =C47/'Income Statemnt'!C6 -> 0.017028549 | Q10: =D47/'Income Statemnt'!D6 -> 0.013647223 | R10: =E47/'Income Statemnt'!E6 -> 0.01144737 | S10: =F47/'Income Statemnt'!F6 -> 0.013883084 | T10: =G47/'Income Statemnt'!G6 -> 0.016399163 | U10: =AVERAGE(Q10:T10) -> 0.01384421
A11: Other investments | B11: 4.4 | C11: 601.8 | D11: 515.8 | E11: 563 | F11: 546 | G11: 454 | O11: Taxation | P11: =C49/'Income Statemnt'!C29 -> 0.065332499 | Q11: =D49/'Income Statemnt'!D29 -> 0.032340469 | R11: =E49/'Income Statemnt'!E29 -> 0.032948465 | S11: =F49/'Income Statemnt'!F29 -> 0.01975945 | T11: =G49/'Income Statemnt'!G29 -> 0.097902098 | U11: =AVERAGE(P11:T11) -> 0.049656596
A12: Loans | B12: 4.5 | C12: 44.3 | D12: 50.4 | E12: 18 | F12: 13 | G12: 11 | O12: Short-term borrowings | Q12: =(D50-C50)/C50 -> 5.9352347 | R12: =(E50-D50)/D50 -> -0.24288897 | S12: =(F50-E50)/E50 -> 0.062690958 | T12: =(G50-F50)/F50 -> -0.87647748 | U12: =AVERAGE(Q12:T12) -> 1.2196398
A13: Deferred taxation asset | B13: 3.2 | C13: 33.6 | D13: 34.3 | E13: 44.2 | F13: 36.3 | G13: 0
A14: Total non-current assets | C14: 11694 | D14: =SUM(D6:D13) -> 11881.3 | E14: =SUM(E6:E13) -> 12968.2 | F14: =SUM(F6:F13) -> 13159.3 | G14: 9896 | H14: =H6+H7+H8+H9+H10+H11+H12+H13 -> 8157.102 | I14: =I6+I7+I8+I9+I10+I11+I12+I13 -> 9292.2892 | J14: =J6+J7+J8+J9+J10+J11+J12+J13 -> 10624.818 | K14: =K6+K7+K8+K9+K10+K11+K12+K13 -> 12187.699 | L14: =L6+L7+L8+L9+L10+L11+L12+L13 -> 14019.503
P15: 2026 | Q15: 2027 | R15: 2028 | S15: 2029 | T15: 2030
A16: CURRENT ASSETS | O16: Net increase/decrease in cash | P16: 2827 | Q16: 2826 | R16: 3488 | S16: 4170 | T16: 4880
A17: Inventories | B17: 4.6 | C17: 5741.1 | D17: 7124.4 | E17: 7503.6 | F17: 7422.9 | G17: 6042 | H17: =-'Income Statemnt'!H7*'Balance sheet'!$U$7 -> 6924.7818 | I17: =-'Income Statemnt'!I7*'Balance sheet'!$U$7 -> 7084.0518 | J17: =-'Income Statemnt'!J7*'Balance sheet'!$U$7 -> 7246.985 | K17: =-'Income Statemnt'!K7*'Balance sheet'!$U$7 -> 7413.6657 | L17: =-'Income Statemnt'!L7*'Balance sheet'!$U$7 -> 7584.18 | P17: ='Cash flow'!H15+'Cash flow'!H32+'Cash flow'!H43 -> 1438.92 | Q17: ='Cash flow'!I15+'Cash flow'!I32+'Cash flow'!I43 -> 2052.5934 | R17: ='Cash flow'!J15+'Cash flow'!J32+'Cash flow'!J43 -> 2670.7778 | S17: ='Cash flow'!K15+'Cash flow'!K32+'Cash flow'!K43 -> 3306.9202 | T17: ='Cash flow'!L15+'Cash flow'!L32+'Cash flow'!L43 -> 3969.7505
